[2025-05-17T09:07:38.425+0000] {taskinstance.py:1083} INFO - Dependencies all met for <TaskInstance: uhi_index_analytics_pipeline_decompose.load_data manual__2025-05-17T05:12:03.413965+00:00 [queued]>
[2025-05-17T09:07:38.449+0000] {taskinstance.py:1083} INFO - Dependencies all met for <TaskInstance: uhi_index_analytics_pipeline_decompose.load_data manual__2025-05-17T05:12:03.413965+00:00 [queued]>
[2025-05-17T09:07:38.450+0000] {taskinstance.py:1279} INFO - 
--------------------------------------------------------------------------------
[2025-05-17T09:07:38.477+0000] {taskinstance.py:1280} INFO - Starting attempt 1 of 2
[2025-05-17T09:07:38.479+0000] {taskinstance.py:1281} INFO - 
--------------------------------------------------------------------------------
[2025-05-17T09:07:38.671+0000] {taskinstance.py:1300} INFO - Executing <Task(PythonOperator): load_data> on 2025-05-17 05:12:03.413965+00:00
[2025-05-17T09:07:38.695+0000] {standard_task_runner.py:55} INFO - Started process 1153 to run task
[2025-05-17T09:07:38.700+0000] {standard_task_runner.py:82} INFO - Running: ['***', 'tasks', 'run', 'uhi_index_analytics_pipeline_decompose', 'load_data', 'manual__2025-05-17T05:12:03.413965+00:00', '--job-id', '210', '--raw', '--subdir', 'DAGS_FOLDER/uhi_pipeline_dag_decompose.py', '--cfg-path', '/tmp/tmpzdp_c4o_']
[2025-05-17T09:07:38.701+0000] {standard_task_runner.py:83} INFO - Job 210: Subtask load_data
[2025-05-17T09:07:38.851+0000] {task_command.py:388} INFO - Running <TaskInstance: uhi_index_analytics_pipeline_decompose.load_data manual__2025-05-17T05:12:03.413965+00:00 [running]> on host ee2bb044a094
[2025-05-17T09:07:39.078+0000] {taskinstance.py:1509} INFO - Exporting the following env vars:
AIRFLOW_CTX_DAG_OWNER=***
AIRFLOW_CTX_DAG_ID=uhi_index_analytics_pipeline_decompose
AIRFLOW_CTX_TASK_ID=load_data
AIRFLOW_CTX_EXECUTION_DATE=2025-05-17T05:12:03.413965+00:00
AIRFLOW_CTX_TRY_NUMBER=1
AIRFLOW_CTX_DAG_RUN_ID=manual__2025-05-17T05:12:03.413965+00:00
[2025-05-17T09:21:00.226+0000] {local_task_job.py:273} WARNING - State of this instance has been externally set to restarting. Terminating instance.
[2025-05-17T09:21:00.457+0000] {process_utils.py:133} INFO - Sending Signals.SIGTERM to group 1153. PIDs of all processes in the group: [1153]
[2025-05-17T09:21:00.468+0000] {process_utils.py:84} INFO - Sending the signal Signals.SIGTERM to group 1153
[2025-05-17T09:21:00.539+0000] {taskinstance.py:1479} ERROR - Received SIGTERM. Terminating subprocesses.
[2025-05-17T09:21:02.782+0000] {taskinstance.py:1768} ERROR - Task failed with exception
Traceback (most recent call last):
  File "/home/airflow/.local/lib/python3.7/site-packages/airflow/operators/python.py", line 175, in execute
    return_value = self.execute_callable()
  File "/home/airflow/.local/lib/python3.7/site-packages/airflow/operators/python.py", line 192, in execute_callable
    return self.python_callable(*self.op_args, **self.op_kwargs)
  File "/opt/airflow/dags/uhi_pipeline_dag_decompose.py", line 67, in load_data
    data = data_loader_local_download.data_loader()
  File "/opt/airflow/project_code/data_pipeline_test/data_loader_local_download.py", line 53, in data_loader
    BUCKET.blob(street_data).download_to_filename(os.path.join(PROJECT_ROOT_IN_CONTAINER, "street.geojson")),
  File "/home/airflow/.local/lib/python3.7/site-packages/google/cloud/storage/blob.py", line 1270, in download_to_filename
    retry=retry,
  File "/home/airflow/.local/lib/python3.7/site-packages/google/cloud/storage/client.py", line 1096, in download_blob_to_file
    retry=retry,
  File "/home/airflow/.local/lib/python3.7/site-packages/google/cloud/storage/blob.py", line 984, in _do_download
    response = download.consume(transport, timeout=timeout)
  File "/home/airflow/.local/lib/python3.7/site-packages/google/resumable_media/requests/download.py", line 233, in consume
    retriable_request, self._get_status_code, self._retry_strategy
  File "/home/airflow/.local/lib/python3.7/site-packages/google/resumable_media/requests/_request_helpers.py", line 148, in wait_and_retry
    response = func()
  File "/home/airflow/.local/lib/python3.7/site-packages/google/resumable_media/requests/download.py", line 228, in retriable_request
    self._write_to_stream(result)
  File "/home/airflow/.local/lib/python3.7/site-packages/google/resumable_media/requests/download.py", line 122, in _write_to_stream
    for chunk in body_iter:
  File "/home/airflow/.local/lib/python3.7/site-packages/requests/models.py", line 816, in generate
    yield from self.raw.stream(chunk_size, decode_content=True)
  File "/home/airflow/.local/lib/python3.7/site-packages/urllib3/response.py", line 628, in stream
    data = self.read(amt=amt, decode_content=decode_content)
  File "/home/airflow/.local/lib/python3.7/site-packages/urllib3/response.py", line 567, in read
    data = self._fp_read(amt) if not fp_closed else b""
  File "/home/airflow/.local/lib/python3.7/site-packages/urllib3/response.py", line 533, in _fp_read
    return self._fp.read(amt) if amt is not None else self._fp.read()
  File "/usr/local/lib/python3.7/http/client.py", line 465, in read
    n = self.readinto(b)
  File "/usr/local/lib/python3.7/http/client.py", line 509, in readinto
    n = self.fp.readinto(b)
  File "/usr/local/lib/python3.7/socket.py", line 589, in readinto
    return self._sock.recv_into(b)
  File "/usr/local/lib/python3.7/ssl.py", line 1071, in recv_into
    return self.read(nbytes, buffer)
  File "/usr/local/lib/python3.7/ssl.py", line 929, in read
    return self._sslobj.read(len, buffer)
  File "/home/airflow/.local/lib/python3.7/site-packages/airflow/models/taskinstance.py", line 1481, in signal_handler
    raise AirflowException("Task received SIGTERM signal")
airflow.exceptions.AirflowException: Task received SIGTERM signal
[2025-05-17T09:21:03.858+0000] {taskinstance.py:1323} INFO - Marking task as UP_FOR_RETRY. dag_id=uhi_index_analytics_pipeline_decompose, task_id=load_data, execution_date=20250517T051203, start_date=20250517T090738, end_date=20250517T092103
[2025-05-17T09:21:05.108+0000] {standard_task_runner.py:105} ERROR - Failed to execute job 210 for task load_data (Task received SIGTERM signal; 1153)
[2025-05-17T09:21:05.857+0000] {process_utils.py:79} INFO - Process psutil.Process(pid=1153, status='terminated', exitcode=1, started='09:07:37') (1153) terminated with exit code 1
