[2025-05-21T07:37:14.716+0000] {taskinstance.py:1083} INFO - Dependencies all met for <TaskInstance: uhi_index_analytics_pipeline_decompose.convert_canopy_to_tiff manual__2025-05-17T05:12:03.413965+00:00 [queued]>
[2025-05-21T07:37:14.756+0000] {taskinstance.py:1083} INFO - Dependencies all met for <TaskInstance: uhi_index_analytics_pipeline_decompose.convert_canopy_to_tiff manual__2025-05-17T05:12:03.413965+00:00 [queued]>
[2025-05-21T07:37:14.758+0000] {taskinstance.py:1279} INFO - 
--------------------------------------------------------------------------------
[2025-05-21T07:37:14.760+0000] {taskinstance.py:1280} INFO - Starting attempt 2 of 2
[2025-05-21T07:37:14.761+0000] {taskinstance.py:1281} INFO - 
--------------------------------------------------------------------------------
[2025-05-21T07:37:14.818+0000] {taskinstance.py:1300} INFO - Executing <Task(PythonOperator): convert_canopy_to_tiff> on 2025-05-17 05:12:03.413965+00:00
[2025-05-21T07:37:14.847+0000] {standard_task_runner.py:55} INFO - Started process 524 to run task
[2025-05-21T07:37:14.855+0000] {standard_task_runner.py:82} INFO - Running: ['***', 'tasks', 'run', 'uhi_index_analytics_pipeline_decompose', 'convert_canopy_to_tiff', 'manual__2025-05-17T05:12:03.413965+00:00', '--job-id', '260', '--raw', '--subdir', 'DAGS_FOLDER/uhi_pipeline_dag_decompose.py', '--cfg-path', '/tmp/tmpojm6rzum']
[2025-05-21T07:37:14.857+0000] {standard_task_runner.py:83} INFO - Job 260: Subtask convert_canopy_to_tiff
[2025-05-21T07:37:15.023+0000] {task_command.py:388} INFO - Running <TaskInstance: uhi_index_analytics_pipeline_decompose.convert_canopy_to_tiff manual__2025-05-17T05:12:03.413965+00:00 [running]> on host ee2bb044a094
[2025-05-21T07:37:15.197+0000] {taskinstance.py:1509} INFO - Exporting the following env vars:
AIRFLOW_CTX_DAG_OWNER=***
AIRFLOW_CTX_DAG_ID=uhi_index_analytics_pipeline_decompose
AIRFLOW_CTX_TASK_ID=convert_canopy_to_tiff
AIRFLOW_CTX_EXECUTION_DATE=2025-05-17T05:12:03.413965+00:00
AIRFLOW_CTX_TRY_NUMBER=2
AIRFLOW_CTX_DAG_RUN_ID=manual__2025-05-17T05:12:03.413965+00:00
[2025-05-21T07:37:54.180+0000] {logging_mixin.py:137} INFO - Using block_size: 4
[2025-05-21T07:38:41.960+0000] {base_job.py:243} ERROR - LocalTaskJob heartbeat got an exception
Traceback (most recent call last):
  File "/home/airflow/.local/lib/python3.7/site-packages/sqlalchemy/engine/base.py", line 3361, in _wrap_pool_connect
    return fn()
  File "/home/airflow/.local/lib/python3.7/site-packages/sqlalchemy/pool/base.py", line 327, in connect
    return _ConnectionFairy._checkout(self)
  File "/home/airflow/.local/lib/python3.7/site-packages/sqlalchemy/pool/base.py", line 894, in _checkout
    fairy = _ConnectionRecord.checkout(pool)
  File "/home/airflow/.local/lib/python3.7/site-packages/sqlalchemy/pool/base.py", line 493, in checkout
    rec = pool._do_get()
  File "/home/airflow/.local/lib/python3.7/site-packages/sqlalchemy/pool/impl.py", line 256, in _do_get
    return self._create_connection()
  File "/home/airflow/.local/lib/python3.7/site-packages/sqlalchemy/pool/base.py", line 273, in _create_connection
    return _ConnectionRecord(self)
  File "/home/airflow/.local/lib/python3.7/site-packages/sqlalchemy/pool/base.py", line 388, in __init__
    self.__connect()
  File "/home/airflow/.local/lib/python3.7/site-packages/sqlalchemy/pool/base.py", line 691, in __connect
    pool.logger.debug("Error on connect(): %s", e)
  File "/home/airflow/.local/lib/python3.7/site-packages/sqlalchemy/util/langhelpers.py", line 72, in __exit__
    with_traceback=exc_tb,
  File "/home/airflow/.local/lib/python3.7/site-packages/sqlalchemy/util/compat.py", line 211, in raise_
    raise exception
  File "/home/airflow/.local/lib/python3.7/site-packages/sqlalchemy/pool/base.py", line 686, in __connect
    self.dbapi_connection = connection = pool._invoke_creator(self)
  File "/home/airflow/.local/lib/python3.7/site-packages/sqlalchemy/engine/create.py", line 578, in connect
    return dialect.connect(*cargs, **cparams)
  File "/home/airflow/.local/lib/python3.7/site-packages/sqlalchemy/engine/default.py", line 598, in connect
    return self.dbapi.connect(*cargs, **cparams)
  File "/home/airflow/.local/lib/python3.7/site-packages/psycopg2/__init__.py", line 122, in connect
    conn = _connect(dsn, connection_factory=connection_factory, **kwasync)
psycopg2.OperationalError: could not translate host name "postgres" to address: Temporary failure in name resolution


The above exception was the direct cause of the following exception:

Traceback (most recent call last):
  File "/home/airflow/.local/lib/python3.7/site-packages/airflow/jobs/base_job.py", line 239, in heartbeat
    self.heartbeat_callback(session=session)
  File "/home/airflow/.local/lib/python3.7/site-packages/airflow/utils/session.py", line 72, in wrapper
    return func(*args, **kwargs)
  File "/home/airflow/.local/lib/python3.7/site-packages/airflow/jobs/local_task_job.py", line 227, in heartbeat_callback
    self.task_instance.refresh_from_db()
  File "/home/airflow/.local/lib/python3.7/site-packages/airflow/utils/session.py", line 75, in wrapper
    return func(*args, session=session, **kwargs)
  File "/home/airflow/.local/lib/python3.7/site-packages/airflow/models/taskinstance.py", line 791, in refresh_from_db
    ti = qry.one_or_none()
  File "/home/airflow/.local/lib/python3.7/site-packages/sqlalchemy/orm/query.py", line 2850, in one_or_none
    return self._iter().one_or_none()
  File "/home/airflow/.local/lib/python3.7/site-packages/sqlalchemy/orm/query.py", line 2919, in _iter
    execution_options={"_sa_orm_load_options": self.load_options},
  File "/home/airflow/.local/lib/python3.7/site-packages/sqlalchemy/orm/session.py", line 1713, in execute
    conn = self._connection_for_bind(bind)
  File "/home/airflow/.local/lib/python3.7/site-packages/sqlalchemy/orm/session.py", line 1553, in _connection_for_bind
    engine, execution_options
  File "/home/airflow/.local/lib/python3.7/site-packages/sqlalchemy/orm/session.py", line 747, in _connection_for_bind
    conn = bind.connect()
  File "/home/airflow/.local/lib/python3.7/site-packages/sqlalchemy/engine/base.py", line 3315, in connect
    return self._connection_cls(self, close_with_result=close_with_result)
  File "/home/airflow/.local/lib/python3.7/site-packages/sqlalchemy/engine/base.py", line 96, in __init__
    else engine.raw_connection()
  File "/home/airflow/.local/lib/python3.7/site-packages/sqlalchemy/engine/base.py", line 3394, in raw_connection
    return self._wrap_pool_connect(self.pool.connect, _connection)
  File "/home/airflow/.local/lib/python3.7/site-packages/sqlalchemy/engine/base.py", line 3365, in _wrap_pool_connect
    e, dialect, self
  File "/home/airflow/.local/lib/python3.7/site-packages/sqlalchemy/engine/base.py", line 2199, in _handle_dbapi_exception_noconnection
    sqlalchemy_exception, with_traceback=exc_info[2], from_=e
  File "/home/airflow/.local/lib/python3.7/site-packages/sqlalchemy/util/compat.py", line 211, in raise_
    raise exception
  File "/home/airflow/.local/lib/python3.7/site-packages/sqlalchemy/engine/base.py", line 3361, in _wrap_pool_connect
    return fn()
  File "/home/airflow/.local/lib/python3.7/site-packages/sqlalchemy/pool/base.py", line 327, in connect
    return _ConnectionFairy._checkout(self)
  File "/home/airflow/.local/lib/python3.7/site-packages/sqlalchemy/pool/base.py", line 894, in _checkout
    fairy = _ConnectionRecord.checkout(pool)
  File "/home/airflow/.local/lib/python3.7/site-packages/sqlalchemy/pool/base.py", line 493, in checkout
    rec = pool._do_get()
  File "/home/airflow/.local/lib/python3.7/site-packages/sqlalchemy/pool/impl.py", line 256, in _do_get
    return self._create_connection()
  File "/home/airflow/.local/lib/python3.7/site-packages/sqlalchemy/pool/base.py", line 273, in _create_connection
    return _ConnectionRecord(self)
  File "/home/airflow/.local/lib/python3.7/site-packages/sqlalchemy/pool/base.py", line 388, in __init__
    self.__connect()
  File "/home/airflow/.local/lib/python3.7/site-packages/sqlalchemy/pool/base.py", line 691, in __connect
    pool.logger.debug("Error on connect(): %s", e)
  File "/home/airflow/.local/lib/python3.7/site-packages/sqlalchemy/util/langhelpers.py", line 72, in __exit__
    with_traceback=exc_tb,
  File "/home/airflow/.local/lib/python3.7/site-packages/sqlalchemy/util/compat.py", line 211, in raise_
    raise exception
  File "/home/airflow/.local/lib/python3.7/site-packages/sqlalchemy/pool/base.py", line 686, in __connect
    self.dbapi_connection = connection = pool._invoke_creator(self)
  File "/home/airflow/.local/lib/python3.7/site-packages/sqlalchemy/engine/create.py", line 578, in connect
    return dialect.connect(*cargs, **cparams)
  File "/home/airflow/.local/lib/python3.7/site-packages/sqlalchemy/engine/default.py", line 598, in connect
    return self.dbapi.connect(*cargs, **cparams)
  File "/home/airflow/.local/lib/python3.7/site-packages/psycopg2/__init__.py", line 122, in connect
    conn = _connect(dsn, connection_factory=connection_factory, **kwasync)
sqlalchemy.exc.OperationalError: (psycopg2.OperationalError) could not translate host name "postgres" to address: Temporary failure in name resolution

(Background on this error at: https://sqlalche.me/e/14/e3q8)
[2025-05-21T07:39:58.149+0000] {logging_mixin.py:137} INFO - Using block_size: 9
[2025-05-21T07:40:56.543+0000] {logging_mixin.py:137} INFO - Using block_size: 28
[2025-05-21T07:41:24.746+0000] {logging_mixin.py:137} INFO - Canopy data converted to TIFF!
[2025-05-21T07:41:24.749+0000] {python.py:177} INFO - Done. Returned value was: True
[2025-05-21T07:41:24.904+0000] {taskinstance.py:1323} INFO - Marking task as SUCCESS. dag_id=uhi_index_analytics_pipeline_decompose, task_id=convert_canopy_to_tiff, execution_date=20250517T051203, start_date=20250521T073714, end_date=20250521T074124
[2025-05-21T07:41:25.098+0000] {local_task_job.py:208} INFO - Task exited with return code 0
[2025-05-21T07:41:25.171+0000] {taskinstance.py:2578} INFO - 0 downstream tasks scheduled from follow-on schedule check
